<mujoco model="go2 scene">
  <include file="go2_push.xml"/>

  <statistic center="0 0 0.1" extent="0.8"/>

  <visual>
    <headlight diffuse="0.6 0.6 0.6" ambient="0.3 0.3 0.3" specular="0 0 0"/>
    <rgba haze="0.15 0.25 0.35 1"/>
    <global azimuth="-130" elevation="-20"/>
  </visual>

  <asset>
    <texture type="skybox" builtin="gradient" rgb1="0.3 0.5 0.7" rgb2="0 0 0" width="512" height="3072"/>
    <texture type="2d" name="groundplane" builtin="checker" mark="edge" rgb1="0.2 0.3 0.4" rgb2="0.1 0.2 0.3"
      markrgb="0.8 0.8 0.8" width="300" height="300"/>
    <material name="groundplane" texture="groundplane" texuniform="true" texrepeat="5 5" reflectance="0.2"/>
  </asset>

  <worldbody>
    <light pos="0 0 1.5" dir="0 0 -1" directional="true"/>
    <geom name="floor" size="0 0 0.05" type="plane" material="groundplane"/>

    <body name="pendulum_pivot" pos="0.0 0.4 0.75">
    <!-- 围绕 y 轴转动，这样球会在 x-z 平面摆动，从侧面撞机器人 -->
    <joint name="pendulum_hinge" type="hinge" axis="1 0 0" damping="0.01"/>

    <!-- 细杆，半长 0.25，总长 0.5 m -->
    <geom name="pendulum_rod"
            type="capsule"
            fromto="0 0 0  0 0 -0.5"
            size="0.01"
            mass="0.05"
            rgba="0.2 0.2 0.2 1"/>

    <!-- 杆末端的重球 -->
    <geom name="pendulum_ball"
            type="sphere"
            pos="0 0 -0.5"
            size="0.05"
            mass="19.0"
            rgba="1 0 0 1"
            friction="0.8 0.1 0.1"/>
    </body>

  </worldbody>
</mujoco>
